<?xml version="1.0" ?>
<!-- =================================================================================== -->
<!-- |    This document was autogenerated by xacro from /home/dave/ros/ws_gazebo/src/gazebo_ros_demos/rrbot_description/urdf/rrbot.xacro | -->
<!-- |    EDITING THIS FILE BY HAND IS NOT RECOMMENDED                                 | -->
<!-- =================================================================================== -->
<!-- Revolute-Revolute Manipulator -->
<robot name="vmd_model" xmlns:xacro="http://www.ros.org/wiki/xacro">
  <!-- Constants for robot dimensions -->
  <!-- Square dimensions (widthxwidth) of beams -->
  <!-- Link 1 -->
  <!-- Link 2 -->
  <!-- Link 3 -->
  <!-- Link 4 -->
  <!-- Size of square 'camera' box -->
  <!-- Space btw top of beam and the each joint -->
  <!-- Import all Gazebo-customization elements, including Gazebo colors -->
  <gazebo>
    <plugin filename="libgazebo_ros_control.so" name="ros_control">
      <robotNamespace>/rrbot</robotNamespace>
    </plugin>
  </gazebo>
  <gazebo reference="base">
    <material>Gazebo/Black</material>
  </gazebo>
  <gazebo reference="ejez">
    <mu1>0.2</mu1>
    <mu2>0.2</mu2>
    <material>Gazebo/Blue</material>
  </gazebo>
  <gazebo reference="ejex">
    <mu1>0.2</mu1>
    <mu2>0.2</mu2>
    <material>Gazebo/Green</material>
  </gazebo>
  <gazebo reference="ejey">
    <mu1>0.2</mu1>
    <mu2>0.2</mu2>
    <material>Gazebo/Red</material>
  </gazebo>
  <gazebo reference="camera_link">
    <mu1>0.2</mu1>
    <mu2>0.2</mu2>
    <material>Gazebo/Red</material>
  </gazebo>
  <gazebo reference="hokuyo_link">
    <sensor name="head_hokuyo_sensor" type="gpu_ray">
      <pose>0 0 0 0 0 0</pose>
      <visualize>false</visualize>
      <update_rate>40</update_rate>
      <ray>
        <scan>
          <horizontal>
            <samples>720</samples>
            <resolution>1</resolution>
            <min_angle>-1.570796</min_angle>
            <max_angle>1.570796</max_angle>
          </horizontal>
        </scan>
        <range>
          <min>0.10</min>
          <max>30.0</max>
          <resolution>0.01</resolution>
        </range>
        <noise>
          <type>gaussian</type>
          <!-- Noise parameters based on published spec for Hokuyo laser
               achieving "+-30mm" accuracy at range < 10m.  A mean of 0.0m and
               stddev of 0.01m will put 99.7% of samples within 0.03m of the true
               reading. -->
          <mean>0.0</mean>
          <stddev>0.01</stddev>
        </noise>
      </ray>
      <plugin filename="libgazebo_ros_gpu_laser.so" name="gazebo_ros_head_hokuyo_controller">
        <topicName>/rrbot/laser/scan</topicName>
        <frameName>hokuyo_link</frameName>
      </plugin>
    </sensor>
  </gazebo>
  <gazebo reference="camera_link">
    <sensor name="camera1" type="camera">
      <update_rate>30.0</update_rate>
      <camera name="head">
        <horizontal_fov>1.3962634</horizontal_fov>
        <image>
          <width>800</width>
          <height>800</height>
          <format>R8G8B8</format>
        </image>
        <clip>
          <near>0.02</near>
          <far>300</far>
        </clip>
        <noise>
          <type>gaussian</type>
          <!-- Noise is sampled independently per pixel on each frame.  
               That pixel's noise value is added to each of its color
               channels, which at that point lie in the range [0,1]. -->
          <mean>0.0</mean>
          <stddev>0.007</stddev>
        </noise>
      </camera>
      <plugin filename="libgazebo_ros_camera.so" name="camera_controller">
        <alwaysOn>true</alwaysOn>
        <updateRate>0.0</updateRate>
        <cameraName>rrbot/camera1</cameraName>
        <imageTopicName>image_raw</imageTopicName>
        <cameraInfoTopicName>camera_info</cameraInfoTopicName>
        <frameName>camera_link</frameName>
        <hackBaseline>0.07</hackBaseline>
        <distortionK1>0.0</distortionK1>
        <distortionK2>0.0</distortionK2>
        <distortionK3>0.0</distortionK3>
        <distortionT1>0.0</distortionT1>
        <distortionT2>0.0</distortionT2>
      </plugin>
    </sensor>
  </gazebo>
  <!-- Import Rviz colors -->
  <material name="black">
    <color rgba="0.0 0.0 0.0 1.0"/>
  </material>
  <material name="blue">
    <color rgba="0.0 0.0 0.8 1.0"/>
  </material>
  <material name="green">
    <color rgba="0.0 0.8 0.0 1.0"/>
  </material>
  <material name="grey">
    <color rgba="0.2 0.2 0.2 1.0"/>
  </material>
  <material name="orange">
    <color rgba="1.0 0.423529411765 0.0392156862745 1.0"/>
  </material>
  <material name="brown">
    <color rgba="0.870588235294 0.811764705882 0.764705882353 1.0"/>
  </material>
  <material name="red">
    <color rgba="0.8 0.0 0.0 1.0"/>
  </material>
  <material name="white">
    <color rgba="1.0 1.0 1.0 1.0"/>
  </material>
  <!-- Used for fixing robot to Gazebo 'base_link' -->
  <link name="world"/>
  <joint name="fixed" type="fixed">
    <parent link="world"/>
    <child link="base"/>
  </joint>
  <!-- Base Link -->
 <link name="base">
    <visual>
      <geometry>
        <mesh filename="package://vmd_model_almacen/vmd_model_description/meshes/link1.dae"/>
      </geometry>
      <origin rpy="1.57075  0 1.57075" xyz="0 0 -0.3"/>
      <material name="white">
        <color rgba="1 1 1 1"/>
      </material>
    </visual>
        </collision>
 <collision>
<xacro:inertial_matrix mass="1"/>
</link>

  <joint name="joint1" type="prismatic">
    <parent link="base"/>
    <child link="ejez"/>
    <origin rpy=" 0  1.57075 1.57075" xyz="0 0 0"/>
     <axis xyz="0 0 1"/>
    <limit effort="1000.0" lower="0" upper="0.76" velocity="0.5"/>
  </joint>

  <!-- Middle Link -->
 <link name="ejez">
    <visual>
     <geometry>
        <box size="0.6 .2 .1"/>
      </geometry>
      <mesh filename="package://vmd_model_almacen/vmd_model_description/meshes/link2.dae"/>
      <material name="white">
        <color rgba="1 1 1 1"/>
      </material>
    </visual>
    <collision>
    </collision>
	<xacro:inertial_matrix mass="1"/>
  </link>

  <joint name="joint2" type="prismatic">
    <parent link="ejez"/>
    <child link="ejex"/>
    <origin rpy="0 0 1.57075" xyz="0 0 0"/>
    <axis xyz="1 0 0" />
    <limit effort="300" velocity="0.1" lower="-4.64" upper="-1.5"/>
    <dynamics damping="50" friction="1"/>
  </joint>
 <!-- Middle Link 2 -->
<link name="ejex">
    <visual>
     <geometry>
        <box size="0.6 .2 .1"/>
      </geometry>
      <mesh filename="package://vmd_model_almacen/vmd_model_description/meshes/link3.dae"/>
      <material name="white">
        <color rgba="1 1 1 1"/>
      </material>      
    </visual>
    <collision>
    </collision>
<xacro:inertial_matrix mass="1"/>
 </link>
  
  <joint name="joint3" type="prismatic">
    <parent link="ejex"/>
    <child link="ejey"/>
    <origin rpy="0 0 1.57075" xyz="0 0 0"/>
    <axis xyz="0 1 0" />
    <limit effort="300" velocity="0.1" lower="-4.64" upper="-1.5"/>
    <dynamics damping="50" friction="1"/>
  </joint>
  <!-- Top Link -->
<link name="ejey">
    <visual>
      <geometry>
        <box size="0.6 .2 .1"/>
      </geometry>
      <mesh filename="package://vmd_model_almacen/vmd_model_description/meshes/link4.dae"/>
      <material name="white">
        <color rgba="1 1 1 1"/>
      </material>
    </visual>
    <collision>
    </collision>
<xacro:inertial_matrix mass="1"/>
 </link>

  <joint name="hokuyo_joint" type="fixed">
    <axis xyz="0 1 0"/>
    <origin rpy="0 0 0" xyz="0 0 0.975"/>
    <parent link="ejey"/>
    <child link="hokuyo_link"/>
  </joint>
  <!-- Hokuyo Laser -->
  <link name="hokuyo_link">
    <collision>
      <origin rpy="0 0 0" xyz="0 0 0"/>
      <geometry>
        <box size="0.1 0.1 0.1"/>
      </geometry>
    </collision>
    <visual>
      <origin rpy="0 0 0" xyz="0 0 0"/>
      <geometry>
        <mesh filename="package://vmd_model_almacen/vmd_description/meshes/hokuyo.dae"/>
      </geometry>
    </visual>
    <inertial>
      <mass value="1e-5"/>
      <origin rpy="0 0 0" xyz="0 0 0"/>
      <inertia ixx="1e-6" ixy="0" ixz="0" iyy="1e-6" iyz="0" izz="1e-6"/>
    </inertial>
  </link>
  <joint name="camera_joint" type="fixed">
    <axis xyz="0 1 0"/>
    <origin rpy="0 0 0" xyz="0.05 0 0.9"/>
    <parent link="link3"/>
    <child link="camera_link"/>
  </joint>
  <!-- Camera -->
  <link name="camera_link">
    <collision>
      <origin rpy="0 0 0" xyz="0 0 0"/>
      <geometry>
        <box size="0.05 0.05 0.05"/>
      </geometry>
    </collision>
    <visual>
      <origin rpy="0 0 0" xyz="0 0 0"/>
      <geometry>
        <box size="0.05 0.05 0.05"/>
      </geometry>
      <material name="red"/>
    </visual>
    <inertial>
      <mass value="1e-5"/>
      <origin rpy="0 0 0" xyz="0 0 0"/>
      <inertia ixx="1e-6" ixy="0" ixz="0" iyy="1e-6" iyz="0" izz="1e-6"/>
    </inertial>
  </link>
  <transmission name="tran1">
    <type>transmission_interface/SimpleTransmission</type>
    <joint name="joint1"/>
        <hardwareinterface>EffortJointInterface</hardwareinterface>
    <actuator name="motor1">
      <hardwareInterface>EffortJointInterface</hardwareInterface>
      <mechanicalReduction>1</mechanicalReduction>
    </actuator>
  </transmission>
  <transmission name="tran2">
    <type>transmission_interface/SimpleTransmission</type>
    <joint name="joint2"/>
      <hardwareinterface>EffortJointInterface</hardwareinterface>
    <actuator name="motor2">
      <hardwareInterface>EffortJointInterface</hardwareInterface>
      <mechanicalReduction>1</mechanicalReduction>
    </actuator>
  </transmission>
  <transmission name="tran3">
    <type>transmission_interface/SimpleTransmission</type>
    <joint name="joint3"/>
       <hardwareinterface>EffortJointInterface</hardwareinterface>
    <actuator name="motor3">
      <hardwareInterface>EffortJointInterface</hardwareInterface>
      <mechanicalReduction>1</mechanicalReduction>
    </actuator>
  </transmission>
</robot>
